<?xml version="1.0" encoding="UTF-8"?>
<!-- Generated by org.testng.reporters.JUnitReportReporter -->
<testsuite hostname="GGKU3SYS304" name="com.ggktech.tests.ReporterListenerExample" tests="3" failures="0" timestamp="18 Apr 2017 07:29:11 GMT" time="0.008" errors="2">
  <testcase name="test1" time="0.007" classname="com.ggktech.tests.ReporterListenerExample"/>
  <testcase name="test2" time="0.001" classname="com.ggktech.tests.ReporterListenerExample">
    <error type="org.testng.TestException" message="
Method ReporterListenerExample.test2()[pri:0, instance:com.ggktech.tests.ReporterListenerExample@6833ce2c] should have thrown an exception of type class java.lang.RuntimeException">
      <![CDATA[org.testng.TestException: 
Method ReporterListenerExample.test2()[pri:0, instance:com.ggktech.tests.ReporterListenerExample@6833ce2c] should have thrown an exception of type class java.lang.RuntimeException
	at org.testng.internal.ExpectedExceptionsHolder.noException(ExpectedExceptionsHolder.java:89)
	at org.testng.internal.Invoker.handleInvocationResults(Invoker.java:1381)
	at org.testng.internal.Invoker.invokeMethod(Invoker.java:681)
	at org.testng.internal.Invoker.invokeTestMethod(Invoker.java:820)
	at org.testng.internal.Invoker.invokeTestMethods(Invoker.java:1128)
	at org.testng.internal.TestMethodWorker.invokeTestMethods(TestMethodWorker.java:129)
	at org.testng.internal.TestMethodWorker.run(TestMethodWorker.java:112)
	at org.testng.TestRunner.privateRun(TestRunner.java:782)
	at org.testng.TestRunner.run(TestRunner.java:632)
	at org.testng.SuiteRunner.runTest(SuiteRunner.java:366)
	at org.testng.SuiteRunner.runSequentially(SuiteRunner.java:361)
	at org.testng.SuiteRunner.privateRun(SuiteRunner.java:319)
	at org.testng.SuiteRunner.run(SuiteRunner.java:268)
	at org.testng.SuiteRunnerWorker.runSuite(SuiteRunnerWorker.java:52)
	at org.testng.SuiteRunnerWorker.run(SuiteRunnerWorker.java:86)
	at org.testng.TestNG.runSuitesSequentially(TestNG.java:1244)
	at org.testng.TestNG.runSuitesLocally(TestNG.java:1169)
	at org.testng.TestNG.run(TestNG.java:1064)
	at org.testng.remote.RemoteTestNG.run(RemoteTestNG.java:113)
	at org.testng.remote.RemoteTestNG.initAndRun(RemoteTestNG.java:206)
	at org.testng.remote.RemoteTestNG.main(RemoteTestNG.java:177)
]]>
    </error>
  </testcase> <!-- test2 -->
  <testcase name="test3" time="0.000" classname="com.ggktech.tests.ReporterListenerExample">
    <error type="java.lang.Throwable" message="Method ReporterListenerExample.test3()[pri:0, instance:com.ggktech.tests.ReporterListenerExample@6833ce2c] depends on not successfully finished methods">
      <![CDATA[java.lang.Throwable: Method ReporterListenerExample.test3()[pri:0, instance:com.ggktech.tests.ReporterListenerExample@6833ce2c] depends on not successfully finished methods
	at org.testng.internal.Invoker.invokeTestMethods(Invoker.java:1037)
	at org.testng.internal.TestMethodWorker.invokeTestMethods(TestMethodWorker.java:129)
	at org.testng.internal.TestMethodWorker.run(TestMethodWorker.java:112)
	at org.testng.TestRunner.privateRun(TestRunner.java:782)
	at org.testng.TestRunner.run(TestRunner.java:632)
	at org.testng.SuiteRunner.runTest(SuiteRunner.java:366)
	at org.testng.SuiteRunner.runSequentially(SuiteRunner.java:361)
	at org.testng.SuiteRunner.privateRun(SuiteRunner.java:319)
	at org.testng.SuiteRunner.run(SuiteRunner.java:268)
	at org.testng.SuiteRunnerWorker.runSuite(SuiteRunnerWorker.java:52)
	at org.testng.SuiteRunnerWorker.run(SuiteRunnerWorker.java:86)
	at org.testng.TestNG.runSuitesSequentially(TestNG.java:1244)
	at org.testng.TestNG.runSuitesLocally(TestNG.java:1169)
	at org.testng.TestNG.run(TestNG.java:1064)
	at org.testng.remote.RemoteTestNG.run(RemoteTestNG.java:113)
	at org.testng.remote.RemoteTestNG.initAndRun(RemoteTestNG.java:206)
	at org.testng.remote.RemoteTestNG.main(RemoteTestNG.java:177)
]]>
    </error>
  </testcase> <!-- test3 -->
</testsuite> <!-- com.ggktech.tests.ReporterListenerExample -->
